Workbook

Sheet 문서표지
S3: 요구사항 추적표
S8: Ver. 0.3 (검토본)
S11: soft2preqcgate1 / 통합(화면·서버)
S12: 예방 품질 관리 시스템(Pre QC Gate)
S13: 46296
S15: 관리부서 : 업무 담당부서 확인 필요
I36: Copyright 2026. Hanwha Ocean Co., Ltd. All rights reserved. | Confidential

Sheet 개정이력
E1: 요구사항 추적표
A4: 개 정 이 력
A6: 버전 | B6: 변경일 | C6: 변경 내용 | D6: 작성자 | E6: 승인자
A7: v0.1 | B7: 46295 | C7: 최초 작성(분석 단계). 프런트엔드 요구사항 정의서 v0.4의 48건을 추적. 프로세스ID·화면ID 잠정 부여, 인터페이스·배치·테이블 "미정", 테스트 "미작성". 추가 열과 잠정 ID 목록·추적 점검 시트 추가. | D7: 분석 담당 | E7: 미승인
A8: v0.2 | B8: 46296 | C8: 프런트엔드 요구사항 정의서 v0.5에 맞춰 소분류를 기능 단위 값으로 변경(48건). | D8: 분석 담당 | E8: 미승인
A9: v0.3 | B9: 46296 | C9: 프런트엔드·백엔드 통합. 통합 요구사항 정의서 v0.6(soft2preqcgate1_요구사항정의서_20261001_1133.xlsx) 53건(RQ-) 기준으로 재작성. 백엔드 원천 31건 반영(서버 전용 5건은 잠정 프로세스 PRC-PQG-150 신설 포함 추적 보강). 결정번호를 통합 번호 DEC-01~DEC-24로 변경. 추가 열을 U~Z(화면 논리 개체, 서버 논리 개체, 통합 결정번호, 확정 여부, 구현 영역, 기존 요구사항ID)로 재편. 추적 점검 시트에 백엔드 개체 26건 역추적 추가. | D9: 분석 담당 | E9: 미승인
A27: ※ 승인 전 작업본은 v0.x, 승인 후 확정본은 v1.0 이상으로 부여한다. 변경 내용에는 변경 위치(시트·행 / 장·절)와 변경 사유를 함께 기재한다.

Sheet 요구사항 추적표
A1: soft2preqcgate1 | T1: 요구사항추적표
A3: 요 구 사 항 | J3: 설 계 | Q3: 개 발 | S3: 테 스 트 | U3: 추 적 보 조
A4: No | B4: 대분류 | C4: 중분류 | D4: 소분류 | E4: 요구사항ID | F4: 요구사항명 | G4: 적용여부 | H4: 프로세스ID | I4: 프로세스명 | J4: 화면ID | K4: 화면명 | L4: 배치프로그램ID | M4: 배치프로그램명 | N4: 인터페이스ID | O4: 인터페이스명 | P4: 테이블ID | Q4: 단위테스트 케이스ID | R4: 단위테스트 케이스명 | S4: 통합테스트 케이스ID | T4: 통합테스트 케이스명 | U4: 화면 논리 개체(FE) | V4: 서버 논리 개체(BE) | W4: 통합 결정번호(DEC) | X4: 확정 여부 | Y4: 구현 영역 | Z4: 기존 요구사항ID
A5: 1 | B5: 예방 품질 관리 | C5: 접속·역할 | D5: 로그인 | E5: RQ-AUTH-001 | F5: 사용자 인증과 역할 결정 | G5: Y | H5: PRC-PQG-010 | I5: 사용자 인증·역할 결정 | J5: PQG-LGN-010-M1 | K5: 로그인 화면 | L5: N/A | M5: N/A | N5: 미정 | O5: 사내 인증 연계 - 인증 사용자·역할 수신(후보, DEC-02) | P5: 미정 | Q5: 미작성 | R5: 개발 단계 작성 | S5: 미작성 | T5: 테스트 단계 작성 | U5: FE-E01 사용자 세션 문맥 | V5: BE:E01 사용자 BE:E02 기자재 담당배정 BE:E24 변경 감사이력 | W5: DEC-01 DEC-02 | X5: 구현 제안 포함 / 결정 필요 | Y5: 화면+서버 | Z5: FE-AUTH-001 BE-AUTH-001
A6: 2 | B6: 예방 품질 관리 | C6: 접속·역할 | D6: 로그아웃 | E6: RQ-AUTH-002 | F6: 로그아웃과 화면상태 초기화 | G6: Y | H6: PRC-PQG-010 | I6: 사용자 인증·역할 결정 | J6: PQG-LGN-010-M1 PQG-DSH-010-M1 | K6: 로그인 화면 대시보드(요약 카드·지표·위험 배너·체계분류 목록) | L6: N/A | M6: N/A | N6: 미정 | O6: 사내 인증 연계 - 인증 사용자·역할 수신(후보, DEC-02) | P6: N/A | Q6: 미작성 | R6: 개발 단계 작성 | S6: 미작성 | T6: 테스트 단계 작성 | U6: FE-E01 사용자 세션 문맥 FE-E02 화면 탐색 상태 | V6: BE:E01 사용자 BE:E02 기자재 담당배정 | W6: DEC-02 | X6: 구현 제안 포함 / 결정 필요 | Y6: 화면 | Z6: FE-AUTH-002
A7: 3 | B7: 예방 품질 관리 | C7: 접속·역할 | D7: 권한 | E7: RQ-AUTH-003 | F7: 역할별 기능 노출과 서버 권한 검증 | G7: Y | H7: PRC-PQG-010 | I7: 사용자 인증·역할 결정 | J7: PQG-DSH-010-M1 PQG-EQP-010-M1 PQG-CFG-010-P1 | K7: 대시보드(요약 카드·지표·위험 배너·체계분류 목록) 기자재 상세(상단 Gate 흐름·판단 영역) 평가기준 설정 창 | L7: N/A | M7: N/A | N7: N/A | O7: N/A | P7: 미정 | Q7: 미작성 | R7: 개발 단계 작성 | S7: 미작성 | T7: 테스트 단계 작성 | U7: FE-E01 사용자 세션 문맥 FE-E02 화면 탐색 상태 | V7: BE:E01 사용자 BE:E02 기자재 담당배정 BE:E05 평가기준 버전 BE:E12 점검 승인판정 BE:E18 해명 품질판정 BE:E20 발주 승인결정 BE:E24 변경 감사이력 | W7: DEC-01 | X7: 구현 제안 포함 / 결정 필요 | Y7: 화면+서버 | Z7: FE-AUTH-003 BE-AUTH-003
A8: 4 | B8: 예방 품질 관리 | C8: 접속·역할 | D8: 권한 | E8: RQ-AUTH-004 | F8: 기자재 담당범위 기준 조회 제한 | G8: Y | H8: PRC-PQG-030 | I8: 기자재 목록·상세 조회 | J8: PQG-DSH-010-M1 PQG-EQP-010-M1 | K8: 대시보드(요약 카드·지표·위험 배너·체계분류 목록) 기자재 상세(상단 Gate 흐름·판단 영역) | L8: N/A | M8: N/A | N8: N/A | O8: N/A | P8: 미정 | Q8: 미작성 | R8: 개발 단계 작성 | S8: 미작성 | T8: 테스트 단계 작성 | U8: FE-E01 사용자 세션 문맥 FE-E04 기자재 목록 행 | V8: BE:E01 사용자 BE:E02 기자재 담당배정 BE:E04 기자재 BE:E22 첨부파일 BE:E23 업무 알림 BE:E03 체계분류 BE:E05 평가기준 버전 BE:E06 위험평가 회차 BE:E19 발주 통제판단 BE:E20 발주 승인결정 | W8: DEC-01 | X8: 구현 제안 포함 / 결정 필요 | Y8: 화면+서버 | Z8: FE-EQUIP-002 BE-AUTH-002
A9: 5 | B9: 예방 품질 관리 | C9: 대시보드 | D9: 조회 | E9: RQ-DASH-001 | F9: 담당범위 요약 카드 표시 | G9: Y | H9: PRC-PQG-020 | I9: 대시보드 현황 조회 | J9: PQG-DSH-010-M1 | K9: 대시보드(요약 카드·지표·위험 배너·체계분류 목록) | L9: N/A | M9: N/A | N9: N/A | O9: N/A | P9: 미정 | Q9: 미작성 | R9: 개발 단계 작성 | S9: 미작성 | T9: 테스트 단계 작성 | U9: FE-E01 사용자 세션 문맥 FE-E03 대시보드 요약 FE-E04 기자재 목록 행 | V9: BE:E01 사용자 BE:E02 기자재 담당배정 BE:E06 위험평가 회차 BE:E19 발주 통제판단 BE:E20 발주 승인결정 BE:E03 체계분류 BE:E04 기자재 BE:E05 평가기준 버전 | W9: DEC-01 | X9: 구현 제안 포함 / 결정 필요 | Y9: 화면 | Z9: FE-DASH-001
A10: 6 | B10: 예방 품질 관리 | C10: 대시보드 | D10: 조회 | E10: RQ-DASH-002 | F10: 점검완료율·사양적합률·발주현황 지표 계산과 표시 | G10: Y | H10: PRC-PQG-020 | I10: 대시보드 현황 조회 | J10: PQG-DSH-010-M1 | K10: 대시보드(요약 카드·지표·위험 배너·체계분류 목록) | L10: N/A | M10: N/A | N10: N/A | O10: N/A | P10: 미정 | Q10: 미작성 | R10: 개발 단계 작성 | S10: 미작성 | T10: 테스트 단계 작성 | U10: FE-E03 대시보드 요약 | V10: BE:E02 기자재 담당배정 BE:E04 기자재 BE:E06 위험평가 회차 BE:E09 기자재 점검항목 BE:E19 발주 통제판단 BE:E20 발주 승인결정 | W10: DEC-03 | X10: 구현 제안 포함 / 결정 필요 | Y10: 화면+서버 | Z10: FE-DASH-002 BE-DASH-001
A11: 7 | B11: 예방 품질 관리 | C11: 대시보드 | D11: 조회 | E11: RQ-DASH-003 | F11: 발주 임박 위험 조회와 알림 배너 표시 | G11: Y | H11: PRC-PQG-020 | I11: 대시보드 현황 조회 | J11: PQG-DSH-010-M1 | K11: 대시보드(요약 카드·지표·위험 배너·체계분류 목록) | L11: N/A | M11: N/A | N11: N/A | O11: N/A | P11: 미정 | Q11: 미작성 | R11: 개발 단계 작성 | S11: 미작성 | T11: 테스트 단계 작성 | U11: FE-E03 대시보드 요약 FE-E05 위험 알림 행 | V11: BE:E02 기자재 담당배정 BE:E04 기자재 BE:E19 발주 통제판단 BE:E20 발주 승인결정 BE:E06 위험평가 회차 | W11: DEC-03 DEC-04 | X11: 구현 제안 포함 / 결정 필요 | Y11: 화면+서버 | Z11: FE-DASH-003 BE-DASH-003
A12: 8 | B12: 예방 품질 관리 | C12: 대시보드 | D12: 필터·검색 | E12: RQ-DASH-004 | F12: 체계분류별 목록 펼침·필터·검색 | G12: Y | H12: PRC-PQG-020 | I12: 대시보드 현황 조회 | J12: PQG-DSH-010-M1 | K12: 대시보드(요약 카드·지표·위험 배너·체계분류 목록) | L12: N/A | M12: N/A | N12: N/A | O12: N/A | P12: N/A | Q12: 미작성 | R12: 개발 단계 작성 | S12: 미작성 | T12: 테스트 단계 작성 | U12: FE-E02 화면 탐색 상태 FE-E04 기자재 목록 행 | V12: BE:E03 체계분류 BE:E04 기자재 BE:E05 평가기준 버전 BE:E06 위험평가 회차 BE:E19 발주 통제판단 BE:E20 발주 승인결정 | W12: N/A | X12: 목업 동작 확인 / 업무 미승인 | Y12: 화면 | Z12: FE-DASH-004
A13: 9 | B13: 예방 품질 관리 | C13: 대시보드 | D13: 필터·검색 | E13: RQ-DASH-005 | F13: 등급 카드 클릭 필터 | G13: Y | H13: PRC-PQG-020 | I13: 대시보드 현황 조회 | J13: PQG-DSH-010-M1 | K13: 대시보드(요약 카드·지표·위험 배너·체계분류 목록) | L13: N/A | M13: N/A | N13: N/A | O13: N/A | P13: N/A | Q13: 미작성 | R13: 개발 단계 작성 | S13: 미작성 | T13: 테스트 단계 작성 | U13: FE-E02 화면 탐색 상태 FE-E03 대시보드 요약 | V13: BE:E02 기자재 담당배정 BE:E06 위험평가 회차 BE:E19 발주 통제판단 BE:E20 발주 승인결정 | W13: N/A | X13: 구현 제안 포함 / 결정 필요 | Y13: 화면 | Z13: FE-DASH-005
A14: 10 | B14: 예방 품질 관리 | C14: 대시보드 | D14: 조회 | E14: RQ-DASH-006 | F14: Gate 판단결과별 현황 지표 표시 | G14: Y | H14: PRC-PQG-020 | I14: 대시보드 현황 조회 | J14: PQG-DSH-010-M1 | K14: 대시보드(요약 카드·지표·위험 배너·체계분류 목록) | L14: 미정 | M14: 잔여조건 보완기한 경과 판정(후보, DEC-23) | N14: N/A | O14: N/A | P14: 미정 | Q14: 미작성 | R14: 개발 단계 작성 | S14: 미작성 | T14: 테스트 단계 작성 | U14: FE-E03 대시보드 요약 FE-E02 화면 탐색 상태 FE-E04 기자재 목록 행 | V14: BE:E02 기자재 담당배정 BE:E06 위험평가 회차 BE:E19 발주 통제판단 BE:E20 발주 승인결정 BE:E03 체계분류 BE:E04 기자재 BE:E05 평가기준 버전 | W14: DEC-03 DEC-23 | X14: 구현 제안 포함 / 결정 필요 | Y14: 화면 | Z14: FE-DASH-006
A15: 11 | B15: 예방 품질 관리 | C15: 기자재 | D15: 조회 | E15: RQ-EQUIP-001 | F15: 기자재·체계분류 목록 조회와 행 표시 | G15: Y | H15: PRC-PQG-030 | I15: 기자재 목록·상세 조회 | J15: PQG-DSH-010-M1 | K15: 대시보드(요약 카드·지표·위험 배너·체계분류 목록) | L15: N/A | M15: N/A | N15: N/A | O15: N/A | P15: 미정 | Q15: 미작성 | R15: 개발 단계 작성 | S15: 미작성 | T15: 테스트 단계 작성 | U15: FE-E04 기자재 목록 행 | V15: BE:E02 기자재 담당배정 BE:E03 체계분류 BE:E04 기자재 BE:E06 위험평가 회차 BE:E05 평가기준 버전 BE:E19 발주 통제판단 BE:E20 발주 승인결정 | W15: DEC-06 DEC-07 | X15: 구현 제안 포함 / 결정 필요 | Y15: 화면+서버 | Z15: FE-EQUIP-001 BE-EQUIP-001
A16: 12 | B16: 예방 품질 관리 | C16: 기자재 | D16: 조회 | E16: RQ-EQUIP-002 | F16: 기자재 상세 진입과 원천 개정 식별 | G16: Y | H16: PRC-PQG-030 | I16: 기자재 목록·상세 조회 | J16: PQG-DSH-010-M1 PQG-EQP-010-M1 | K16: 대시보드(요약 카드·지표·위험 배너·체계분류 목록) 기자재 상세(상단 Gate 흐름·판단 영역) | L16: N/A | M16: N/A | N16: N/A | O16: N/A | P16: 미정 | Q16: 미작성 | R16: 개발 단계 작성 | S16: 미작성 | T16: 테스트 단계 작성 | U16: FE-E04 기자재 목록 행 FE-E09 위험도 산정 근거 | V16: BE:E04 기자재 BE:E06 위험평가 회차 BE:E09 기자재 점검항목 BE:E13 사양비교 개정 BE:E14 사양비교 항목 BE:E19 발주 통제판단 BE:E03 체계분류 BE:E05 평가기준 버전 BE:E20 발주 승인결정 BE:E07 평가요소 | W16: DEC-06 DEC-13 | X16: 구현 제안 포함 / 결정 필요 | Y16: 화면+서버 | Z16: FE-EQUIP-003 BE-EQUIP-002
... A57: 53 | B57: 예방 품질 관리 | C57: 알림 | D57: 알림 | E57: RQ-NOTIF-005 | F57: 위험 알림 수신범위와 발송정책 구분 | G57: Y | H57: PRC-PQG-140 | I57: 업무 알림 | J57: PQG-DSH-010-M1 PQG-NTF-010-M1 | K57: 대시보드(요약 카드·지표·위험 배너·체계분류 목록) 알림 트레이 | L57: 미정 | M57: 위험 알림 정기 발송(후보, DEC-04 DEC-15) | N57: 미정 | O57: 업무 알림 외부 발송(후보, DEC-05) | P57: 미정 | Q57: 미작성 | R57: 개발 단계 작성 | S57: 미작성 | T57: 테스트 단계 작성 | U57: N/A | V57: BE:E02 기자재 담당배정 BE:E04 기자재 BE:E19 발주 통제판단 BE:E23 업무 알림 | W57: DEC-04 DEC-15 | X57: 구현 제안 포함 / 결정 필요 | Y57: 서버 | Z57: BE-NOTIF-002
A59: ※ 적용여부 Y는 분석 단계 기준 시스템 반영 대상이라는 뜻이며, 업무 승인 여부는 X열(확정 여부)과 W열(통합 결정번호)을 따른다. 프로세스ID·화면ID는 "잠정 ID 목록" 시트의 잠정 ID이다. "미정"은 해당 가능성이 있으나 설계 문서가 없거나 결정 전인 항목, "N/A"는 해당 없음이다. Y열(구현 영역)은 화면(프런트엔드)·서버(백엔드) 구현 범위, Z열은 통합 전 원천 요구사항ID이다.

Sheet 잠정 ID 목록
A1: 잠정 프로세스ID·화면ID 목록
A2: 프로세스 정의서·프로그램 설계서 작성 전 추적용 잠정 ID. 정식 ID가 부여되면 요구사항 추적표 H·J열과 함께 교체한다. 추적 요구사항 수는 요구사항 추적표를 세는 수식이다.
A4: 1. 잠정 프로세스
A5: 프로세스ID | B5: 프로세스명 | C5: 대상 요구사항 | D5: 근거 | E5: 비고 | F5: 추적 요구사항 수
A6: PRC-PQG-010 | B6: 사용자 인증·역할 결정 | C6: RQ-AUTH-001, RQ-AUTH-002, RQ-AUTH-003 | D6: 목업 initLogin/selPersona/doLogin/doLogout (377~404행) | E6: 목업 기반 | F6: =COUNTIF('요구사항 추적표'!$H$5:$H$57,A6)
A7: PRC-PQG-020 | B7: 대시보드 현황 조회 | C7: RQ-DASH-001, RQ-DASH-002, RQ-DASH-003, RQ-DASH-004, RQ-DASH-005, RQ-DASH-006 | D7: 목업 renderDash (434~598행) | E7: 목업 기반 | F7: =COUNTIF('요구사항 추적표'!$H$5:$H$57,A7)
A8: PRC-PQG-030 | B8: 기자재 목록·상세 조회 | C8: RQ-AUTH-004, RQ-EQUIP-001, RQ-EQUIP-002, RQ-EQUIP-003 | D8: 목업 renderDash, openDetail/closeDet (540~666행) | E8: 목업 기반 | F8: =COUNTIF('요구사항 추적표'!$H$5:$H$57,A8)
A9: PRC-PQG-040 | B9: 위험도 산정 결과 조회 | C9: RQ-SCORE-001, RQ-SCORE-002, RQ-SCORE-003 | D9: 목업 grade, renderScore (285, 669~790행) | E9: 목업 기반 | F9: =COUNTIF('요구사항 추적표'!$H$5:$H$57,A9)
A10: PRC-PQG-050 | B10: 점수 시뮬레이션 | C10: RQ-SCORE-004 | D10: 목업 openSim/calcSim (1237~1258행) | E10: 목업 기반 | F10: =COUNTIF('요구사항 추적표'!$H$5:$H$57,A10)
A11: PRC-PQG-060 | B11: 과거 교훈 점검·증빙 승인 | C11: RQ-LL-001, RQ-LL-002, RQ-LL-003, RQ-LL-004, RQ-LL-005, RQ-LL-006, RQ-LL-007 | D11: 목업 renderLL/simUp/reqAppr/doAppr (841~904행) | E11: 목업 기반 | F11: =COUNTIF('요구사항 추적표'!$H$5:$H$57,A11)
A12: PRC-PQG-070 | B12: 사양 비교·해명·품질 판정 | C12: RQ-SPEC-001, RQ-SPEC-002, RQ-SPEC-003, RQ-SPEC-004, RQ-SPEC-005, RQ-SPEC-006 | D12: 목업 renderPOS/openPosModal/posDecision (906~1200행) | E12: 목업 기반 | F12: =COUNTIF('요구사항 추적표'!$H$5:$H$57,A12)
A13: PRC-PQG-080 | B13: Gate 통제 판단·발주 진행 승인 | C13: RQ-GATE-001, RQ-GATE-002, RQ-GATE-003, RQ-GATE-004, RQ-GATE-005, RQ-GATE-006, RQ-GATE-007, RQ-GATE-008, RQ-GATE-013, RQ-GATE-014 | D13: 목업 openDetail/unlockOrder (623~651, 832~838행) | E13: 목업 기반 | F13: =COUNTIF('요구사항 추적표'!$H$5:$H$57,A13)
A14: PRC-PQG-090 | B14: 조건부 통과 잔여조건 관리 | C14: RQ-GATE-009 | D14: 목업 없음(설명 보고서 제5장 기반 제안) | E14: 제안 신규 | F14: =COUNTIF('요구사항 추적표'!$H$5:$H$57,A14)
A15: PRC-PQG-100 | B15: 승인 후 변경 재검토 | C15: RQ-GATE-010 | D15: 목업 없음(설명 보고서 제9장 기반 제안) | E15: 제안 신규 | F15: =COUNTIF('요구사항 추적표'!$H$5:$H$57,A15)
A16: PRC-PQG-110 | B16: 발주서 단위 통제 | C16: RQ-GATE-011 | D16: 목업 없음(설명 보고서 제7장 기반 제안, FD16) | E16: 제안 신규 | F16: =COUNTIF('요구사항 추적표'!$H$5:$H$57,A16)
A17: PRC-PQG-120 | B17: 승인 결과 외부 전달 | C17: RQ-GATE-012 | D17: 목업 unlockOrder 안내 문구(836행)만 존재 | E17: 목업 기반 | F17: =COUNTIF('요구사항 추적표'!$H$5:$H$57,A17)
... A20: PRC-PQG-150 | B20: 외부 원천 데이터 연계 | C20: RQ-CONFIG-004 | D20: 목업 화면 문구(PM Portal·PLM·ERP)만 존재, 백엔드 BE-CONFIG-003 기반 제안 | E20: 제안 신규 | F20: =COUNTIF('요구사항 추적표'!$H$5:$H$57,A20)
A23: 2. 잠정 화면
A24: 화면ID | B24: 화면명 | C24: 대상 요구사항 | D24: 근거 / 구분 | E24: 비고 | F24: 추적 요구사항 수
A25: PQG-LGN-010-M1 | B25: 로그인 화면 | C25: RQ-AUTH-001, RQ-AUTH-002 | D25: 목업 initLogin (377~397행) / 목업 존재 | E25: M1=기본 화면·영역 | F25: =SUMPRODUCT(--ISNUMBER(FIND(A25,'요구사항 추적표'!$J$5:$J$57)))
A26: PQG-DSH-010-M1 | B26: 대시보드(요약 카드·지표·위험 배너·체계분류 목록) | C26: RQ-AUTH-002, RQ-AUTH-003, RQ-AUTH-004, RQ-DASH-001, RQ-DASH-002, RQ-DASH-003, RQ-DASH-004, RQ-DASH-005, RQ-DASH-006, RQ-EQUIP-001, RQ-EQUIP-002, RQ-SCORE-001, RQ-LL-005, RQ-SPEC-006, RQ-GATE-002, RQ-GATE-005, RQ-GATE-007, RQ-GATE-010, RQ-GATE-011, RQ-CONFIG-002, RQ-NOTIF-004, RQ-NOTIF-005 | D26: 목업 renderDash (434~598행) / 목업 존재 | E26: M1=기본 화면·영역 | F26: =SUMPRODUCT(--ISNUMBER(FIND(A26,'요구사항 추적표'!$J$5:$J$57)))
A27: PQG-EQP-010-M1 | B27: 기자재 상세(상단 Gate 흐름·판단 영역) | C27: RQ-AUTH-003, RQ-AUTH-004, RQ-EQUIP-002, RQ-EQUIP-003, RQ-GATE-001, RQ-GATE-002, RQ-GATE-003, RQ-GATE-004, RQ-GATE-006, RQ-GATE-007, RQ-GATE-010, RQ-GATE-012, RQ-NOTIF-002 | D27: 목업 openDetail (600~666행) / 목업 존재 + 영역 추가 제안 | E27: M1=기본 화면·영역 | F27: =SUMPRODUCT(--ISNUMBER(FIND(A27,'요구사항 추적표'!$J$5:$J$57)))
A28: PQG-EQP-020-M1 | B28: 교훈 점검 탭 | C28: RQ-EQUIP-003, RQ-LL-001, RQ-LL-002, RQ-LL-003, RQ-LL-004, RQ-LL-005, RQ-LL-006, RQ-LL-007, RQ-GATE-008 | D28: 목업 renderLL (841~888행) / 목업 존재 | E28: M1=기본 화면·영역 | F28: =SUMPRODUCT(--ISNUMBER(FIND(A28,'요구사항 추적표'!$J$5:$J$57)))
A29: PQG-EQP-030-M1 | B29: 사양 비교 탭 | C29: RQ-EQUIP-003, RQ-SPEC-001, RQ-SPEC-004, RQ-SPEC-005, RQ-SPEC-006, RQ-GATE-008 | D29: 목업 renderPOS (906~969행) / 목업 존재 | E29: M1=기본 화면·영역 | F29: =SUMPRODUCT(--ISNUMBER(FIND(A29,'요구사항 추적표'!$J$5:$J$57)))
A30: PQG-EQP-031-P1 | B30: 사양 해명 작성·검토 창 | C30: RQ-SPEC-002, RQ-SPEC-003, RQ-SPEC-004, RQ-SPEC-005 | D30: 목업 openPosModal (974~1200행) / 목업 존재 | E30: P1=팝업 창 | F30: =SUMPRODUCT(--ISNUMBER(FIND(A30,'요구사항 추적표'!$J$5:$J$57)))
A31: PQG-EQP-040-M1 | B31: 위험도 산정 근거 탭 | C31: RQ-EQUIP-003, RQ-SCORE-001, RQ-SCORE-002, RQ-SCORE-003 | D31: 목업 renderScore (669~790행) / 목업 존재 | E31: M1=기본 화면·영역 | F31: =SUMPRODUCT(--ISNUMBER(FIND(A31,'요구사항 추적표'!$J$5:$J$57)))
A32: PQG-EQP-050-P1 | B32: 발주 진행 승인 입력 창(정상·조건부) | C32: RQ-GATE-003, RQ-GATE-004 | D32: 목업 unlockOrder confirm (833행) / 제안 신규(목업은 확인 대화상자만) | E32: P1=팝업 창 | F32: =SUMPRODUCT(--ISNUMBER(FIND(A32,'요구사항 추적표'!$J$5:$J$57)))
A33: PQG-EQP-060-M1 | B33: Gate 필수조건·판단 단계 영역 | C33: RQ-GATE-008, RQ-GATE-013 | D33: 요구사항 FE-GATE-008, FE-GATE-013 / 제안 신규 | E33: M1=기본 화면·영역 | F33: =SUMPRODUCT(--ISNUMBER(FIND(A33,'요구사항 추적표'!$J$5:$J$57)))
A34: PQG-EQP-070-M1 | B34: 조건부 통과 잔여조건 영역 | C34: RQ-GATE-009 | D34: 요구사항 FE-GATE-009 / 제안 신규 | E34: M1=기본 화면·영역 | F34: =SUMPRODUCT(--ISNUMBER(FIND(A34,'요구사항 추적표'!$J$5:$J$57)))
A35: PQG-POD-010-M1 | B35: 발주서 통제 보기 | C35: RQ-GATE-011 | D35: 요구사항 FE-GATE-011 / 제안 신규(FD16 결정 후) | E35: M1=기본 화면·영역 | F35: =SUMPRODUCT(--ISNUMBER(FIND(A35,'요구사항 추적표'!$J$5:$J$57)))
A36: PQG-SIM-010-P1 | B36: 점수 시뮬레이터 창 | C36: RQ-SCORE-001, RQ-SCORE-004, RQ-CONFIG-003 | D36: 목업 openSim (1237~1258행) / 목업 존재 | E36: P1=팝업 창 | F36: =SUMPRODUCT(--ISNUMBER(FIND(A36,'요구사항 추적표'!$J$5:$J$57)))
... A39: PQG-CMN-010-M1 | B39: 처리 결과 안내 메시지(공통) | C39: RQ-NOTIF-003 | D39: 목업 toast (1303행) / 목업 존재 | E39: M1=기본 화면·영역 | F39: =SUMPRODUCT(--ISNUMBER(FIND(A39,'요구사항 추적표'!$J$5:$J$57)))

Sheet 추적 점검
A1: 추적 점검(정방향·역방향)
A2: 건수 열은 요구사항 추적표를 세는 수식이다. 요구사항ID 목록은 작성 시점 값이다.
A4: 1. 중분류별 추적 현황
A5: 중분류 | B5: 요구사항 수 | C5: 화면+서버 | D5: 화면 | E5: 서버 | F5: 결정 필요 | G5: 인터페이스 후보 | H5: 요구사항ID
A6: 접속·역할 | B6: =COUNTIF('요구사항 추적표'!$C$5:$C$57,A6) | C6: =COUNTIFS('요구사항 추적표'!$C$5:$C$57,A6,'요구사항 추적표'!$Y$5:$Y$57,"화면+서버") | D6: =COUNTIFS('요구사항 추적표'!$C$5:$C$57,A6,'요구사항 추적표'!$Y$5:$Y$57,"화면") | E6: =COUNTIFS('요구사항 추적표'!$C$5:$C$57,A6,'요구사항 추적표'!$Y$5:$Y$57,"서버") | F6: =COUNTIFS('요구사항 추적표'!$C$5:$C$57,A6,'요구사항 추적표'!$X$5:$X$57,"*결정 필요*") | G6: =COUNTIFS('요구사항 추적표'!$C$5:$C$57,A6,'요구사항 추적표'!$N$5:$N$57,"미정") | H6: RQ-AUTH-001, RQ-AUTH-002, RQ-AUTH-003, RQ-AUTH-004
A7: 대시보드 | B7: =COUNTIF('요구사항 추적표'!$C$5:$C$57,A7) | C7: =COUNTIFS('요구사항 추적표'!$C$5:$C$57,A7,'요구사항 추적표'!$Y$5:$Y$57,"화면+서버") | D7: =COUNTIFS('요구사항 추적표'!$C$5:$C$57,A7,'요구사항 추적표'!$Y$5:$Y$57,"화면") | E7: =COUNTIFS('요구사항 추적표'!$C$5:$C$57,A7,'요구사항 추적표'!$Y$5:$Y$57,"서버") | F7: =COUNTIFS('요구사항 추적표'!$C$5:$C$57,A7,'요구사항 추적표'!$X$5:$X$57,"*결정 필요*") | G7: =COUNTIFS('요구사항 추적표'!$C$5:$C$57,A7,'요구사항 추적표'!$N$5:$N$57,"미정") | H7: RQ-DASH-001, RQ-DASH-002, RQ-DASH-003, RQ-DASH-004, RQ-DASH-005, RQ-DASH-006
A8: 기자재 | B8: =COUNTIF('요구사항 추적표'!$C$5:$C$57,A8) | C8: =COUNTIFS('요구사항 추적표'!$C$5:$C$57,A8,'요구사항 추적표'!$Y$5:$Y$57,"화면+서버") | D8: =COUNTIFS('요구사항 추적표'!$C$5:$C$57,A8,'요구사항 추적표'!$Y$5:$Y$57,"화면") | E8: =COUNTIFS('요구사항 추적표'!$C$5:$C$57,A8,'요구사항 추적표'!$Y$5:$Y$57,"서버") | F8: =COUNTIFS('요구사항 추적표'!$C$5:$C$57,A8,'요구사항 추적표'!$X$5:$X$57,"*결정 필요*") | G8: =COUNTIFS('요구사항 추적표'!$C$5:$C$57,A8,'요구사항 추적표'!$N$5:$N$57,"미정") | H8: RQ-EQUIP-001, RQ-EQUIP-002, RQ-EQUIP-003
A9: 위험평가 | B9: =COUNTIF('요구사항 추적표'!$C$5:$C$57,A9) | C9: =COUNTIFS('요구사항 추적표'!$C$5:$C$57,A9,'요구사항 추적표'!$Y$5:$Y$57,"화면+서버") | D9: =COUNTIFS('요구사항 추적표'!$C$5:$C$57,A9,'요구사항 추적표'!$Y$5:$Y$57,"화면") | E9: =COUNTIFS('요구사항 추적표'!$C$5:$C$57,A9,'요구사항 추적표'!$Y$5:$Y$57,"서버") | F9: =COUNTIFS('요구사항 추적표'!$C$5:$C$57,A9,'요구사항 추적표'!$X$5:$X$57,"*결정 필요*") | G9: =COUNTIFS('요구사항 추적표'!$C$5:$C$57,A9,'요구사항 추적표'!$N$5:$N$57,"미정") | H9: RQ-SCORE-001, RQ-SCORE-002, RQ-SCORE-003, RQ-SCORE-004
A10: 점검·증빙 | B10: =COUNTIF('요구사항 추적표'!$C$5:$C$57,A10) | C10: =COUNTIFS('요구사항 추적표'!$C$5:$C$57,A10,'요구사항 추적표'!$Y$5:$Y$57,"화면+서버") | D10: =COUNTIFS('요구사항 추적표'!$C$5:$C$57,A10,'요구사항 추적표'!$Y$5:$Y$57,"화면") | E10: =COUNTIFS('요구사항 추적표'!$C$5:$C$57,A10,'요구사항 추적표'!$Y$5:$Y$57,"서버") | F10: =COUNTIFS('요구사항 추적표'!$C$5:$C$57,A10,'요구사항 추적표'!$X$5:$X$57,"*결정 필요*") | G10: =COUNTIFS('요구사항 추적표'!$C$5:$C$57,A10,'요구사항 추적표'!$N$5:$N$57,"미정") | H10: RQ-LL-001, RQ-LL-002, RQ-LL-003, RQ-LL-004, RQ-LL-005, RQ-LL-006, RQ-LL-007
A11: 사양비교·해명 | B11: =COUNTIF('요구사항 추적표'!$C$5:$C$57,A11) | C11: =COUNTIFS('요구사항 추적표'!$C$5:$C$57,A11,'요구사항 추적표'!$Y$5:$Y$57,"화면+서버") | D11: =COUNTIFS('요구사항 추적표'!$C$5:$C$57,A11,'요구사항 추적표'!$Y$5:$Y$57,"화면") | E11: =COUNTIFS('요구사항 추적표'!$C$5:$C$57,A11,'요구사항 추적표'!$Y$5:$Y$57,"서버") | F11: =COUNTIFS('요구사항 추적표'!$C$5:$C$57,A11,'요구사항 추적표'!$X$5:$X$57,"*결정 필요*") | G11: =COUNTIFS('요구사항 추적표'!$C$5:$C$57,A11,'요구사항 추적표'!$N$5:$N$57,"미정") | H11: RQ-SPEC-001, RQ-SPEC-002, RQ-SPEC-003, RQ-SPEC-004, RQ-SPEC-005, RQ-SPEC-006
A12: 발주통제 | B12: =COUNTIF('요구사항 추적표'!$C$5:$C$57,A12) | C12: =COUNTIFS('요구사항 추적표'!$C$5:$C$57,A12,'요구사항 추적표'!$Y$5:$Y$57,"화면+서버") | D12: =COUNTIFS('요구사항 추적표'!$C$5:$C$57,A12,'요구사항 추적표'!$Y$5:$Y$57,"화면") | E12: =COUNTIFS('요구사항 추적표'!$C$5:$C$57,A12,'요구사항 추적표'!$Y$5:$Y$57,"서버") | F12: =COUNTIFS('요구사항 추적표'!$C$5:$C$57,A12,'요구사항 추적표'!$X$5:$X$57,"*결정 필요*") | G12: =COUNTIFS('요구사항 추적표'!$C$5:$C$57,A12,'요구사항 추적표'!$N$5:$N$57,"미정") | H12: RQ-GATE-001, RQ-GATE-002, RQ-GATE-003, RQ-GATE-004, RQ-GATE-005, RQ-GATE-006, RQ-GATE-007, RQ-GATE-008, RQ-GATE-009, RQ-GATE-010, RQ-GATE-011, RQ-GATE-012, RQ-GATE-013, RQ-GATE-014
A13: 평가기준 | B13: =COUNTIF('요구사항 추적표'!$C$5:$C$57,A13) | C13: =COUNTIFS('요구사항 추적표'!$C$5:$C$57,A13,'요구사항 추적표'!$Y$5:$Y$57,"화면+서버") | D13: =COUNTIFS('요구사항 추적표'!$C$5:$C$57,A13,'요구사항 추적표'!$Y$5:$Y$57,"화면") | E13: =COUNTIFS('요구사항 추적표'!$C$5:$C$57,A13,'요구사항 추적표'!$Y$5:$Y$57,"서버") | F13: =COUNTIFS('요구사항 추적표'!$C$5:$C$57,A13,'요구사항 추적표'!$X$5:$X$57,"*결정 필요*") | G13: =COUNTIFS('요구사항 추적표'!$C$5:$C$57,A13,'요구사항 추적표'!$N$5:$N$57,"미정") | H13: RQ-CONFIG-001, RQ-CONFIG-002, RQ-CONFIG-003, RQ-CONFIG-004
A14: 알림 | B14: =COUNTIF('요구사항 추적표'!$C$5:$C$57,A14) | C14: =COUNTIFS('요구사항 추적표'!$C$5:$C$57,A14,'요구사항 추적표'!$Y$5:$Y$57,"화면+서버") | D14: =COUNTIFS('요구사항 추적표'!$C$5:$C$57,A14,'요구사항 추적표'!$Y$5:$Y$57,"화면") | E14: =COUNTIFS('요구사항 추적표'!$C$5:$C$57,A14,'요구사항 추적표'!$Y$5:$Y$57,"서버") | F14: =COUNTIFS('요구사항 추적표'!$C$5:$C$57,A14,'요구사항 추적표'!$X$5:$X$57,"*결정 필요*") | G14: =COUNTIFS('요구사항 추적표'!$C$5:$C$57,A14,'요구사항 추적표'!$N$5:$N$57,"미정") | H14: RQ-NOTIF-001, RQ-NOTIF-002, RQ-NOTIF-003, RQ-NOTIF-004, RQ-NOTIF-005
A15: 합계 | B15: =SUM(B6:B14) | C15: =SUM(C6:C14) | D15: =SUM(D6:D14) | E15: =SUM(E6:E14) | F15: =SUM(F6:F14) | G15: =SUM(G6:G14)
A17: 2. 화면 논리 개체 역추적(프런트엔드 데이터 모델 정의서 v0.3 → 요구사항)
A18: 개체ID | B18: 개체명 | C18: 추적 요구사항 수 | D18: 판정 | H18: 요구사항ID
A19: FE-E01 | B19: 사용자 세션 문맥 | C19: =SUMPRODUCT(--ISNUMBER(FIND(A19&" ",'요구사항 추적표'!$U$5:$U$57))) | D19: 정상 | H19: RQ-AUTH-001, RQ-AUTH-002, RQ-AUTH-003, RQ-AUTH-004, RQ-DASH-001, RQ-NOTIF-001
A20: FE-E02 | B20: 화면 탐색 상태 | C20: =SUMPRODUCT(--ISNUMBER(FIND(A20&" ",'요구사항 추적표'!$U$5:$U$57))) | D20: 정상 | H20: RQ-AUTH-002, RQ-AUTH-003, RQ-DASH-004, RQ-DASH-005, RQ-DASH-006
A21: FE-E03 | B21: 대시보드 요약 | C21: =SUMPRODUCT(--ISNUMBER(FIND(A21&" ",'요구사항 추적표'!$U$5:$U$57))) | D21: 정상 | H21: RQ-DASH-001, RQ-DASH-002, RQ-DASH-003, RQ-DASH-005, RQ-DASH-006, RQ-LL-005, RQ-NOTIF-004
A22: FE-E04 | B22: 기자재 목록 행 | C22: =SUMPRODUCT(--ISNUMBER(FIND(A22&" ",'요구사항 추적표'!$U$5:$U$57))) | D22: 정상 | H22: RQ-AUTH-004, RQ-DASH-001, RQ-DASH-004, RQ-DASH-006, RQ-EQUIP-001, RQ-EQUIP-002, RQ-SCORE-001, RQ-LL-001, RQ-SPEC-001, RQ-GATE-001, RQ-GATE-002, RQ-GATE-003, RQ-GATE-004, RQ-GATE-006, RQ-GATE-007, RQ-GATE-010, RQ-GATE-011, RQ-GATE-013, RQ-CONFIG-002, RQ-CONFIG-003, RQ-NOTIF-002
A23: FE-E05 | B23: 위험 알림 행 | C23: =SUMPRODUCT(--ISNUMBER(FIND(A23&" ",'요구사항 추적표'!$U$5:$U$57))) | D23: 정상 | H23: RQ-DASH-003, RQ-LL-005, RQ-GATE-005, RQ-GATE-007, RQ-NOTIF-004
A24: FE-E06 | B24: 점검 항목 행 | C24: =SUMPRODUCT(--ISNUMBER(FIND(A24&" ",'요구사항 추적표'!$U$5:$U$57))) | D24: 정상 | H24: RQ-EQUIP-003, RQ-LL-001, RQ-LL-002, RQ-LL-003, RQ-LL-004, RQ-LL-005, RQ-LL-007, RQ-GATE-008
A25: FE-E07 | B25: 점검 처리 입력 | C25: =SUMPRODUCT(--ISNUMBER(FIND(A25&" ",'요구사항 추적표'!$U$5:$U$57))) | D25: 정상 | H25: RQ-LL-002
A26: FE-E08 | B26: 점검 승인요청 입력 | C26: =SUMPRODUCT(--ISNUMBER(FIND(A26&" ",'요구사항 추적표'!$U$5:$U$57))) | D26: 정상 | H26: RQ-LL-003
A27: FE-E09 | B27: 위험도 산정 근거 | C27: =SUMPRODUCT(--ISNUMBER(FIND(A27&" ",'요구사항 추적표'!$U$5:$U$57))) | D27: 정상 | H27: RQ-EQUIP-002, RQ-EQUIP-003, RQ-SCORE-001, RQ-SCORE-002, RQ-SCORE-003, RQ-GATE-001, RQ-GATE-002
A28: FE-E10 | B28: 참조 이력 행 | C28: =SUMPRODUCT(--ISNUMBER(FIND(A28&" ",'요구사항 추적표'!$U$5:$U$57))) | D28: 정상 | H28: RQ-SCORE-002
A29: FE-E11 | B29: 평가기준 설정 표시 | C29: =SUMPRODUCT(--ISNUMBER(FIND(A29&" ",'요구사항 추적표'!$U$5:$U$57))) | D29: 정상 | H29: RQ-SCORE-004, RQ-CONFIG-001, RQ-CONFIG-002, RQ-CONFIG-003
A30: FE-E12 | B30: 평가기준 적용 입력 | C30: =SUMPRODUCT(--ISNUMBER(FIND(A30&" ",'요구사항 추적표'!$U$5:$U$57))) | D30: 정상 | H30: RQ-CONFIG-001, RQ-CONFIG-002, RQ-CONFIG-003
... A47: FE-E29 | B47: 잔여조건 이행 처리 입력 | C47: =SUMPRODUCT(--ISNUMBER(FIND(A47&" ",'요구사항 추적표'!$U$5:$U$57))) | D47: 정상 | H47: RQ-GATE-009
A50: 3. 서버 논리 개체 역추적(백엔드 데이터 모델 정의서 v0.1 → 요구사항)
A51: 개체ID | B51: 개체명 | C51: 추적 요구사항 수 | D51: 판정 | H51: 요구사항ID
A52: BE:E01 | B52: 사용자 | C52: =SUMPRODUCT(--ISNUMBER(FIND(A52&" ",'요구사항 추적표'!$V$5:$V$57))) | D52: 정상 | H52: RQ-AUTH-001, RQ-AUTH-002, RQ-AUTH-003, RQ-AUTH-004, RQ-DASH-001, RQ-CONFIG-001, RQ-NOTIF-001, RQ-NOTIF-004
A53: BE:E02 | B53: 기자재 담당배정 | C53: =SUMPRODUCT(--ISNUMBER(FIND(A53&" ",'요구사항 추적표'!$V$5:$V$57))) | D53: 정상 | H53: RQ-AUTH-001, RQ-AUTH-002, RQ-AUTH-003, RQ-AUTH-004, RQ-DASH-001, RQ-DASH-002, RQ-DASH-003, RQ-DASH-005, RQ-DASH-006, RQ-EQUIP-001, RQ-LL-005, RQ-NOTIF-001, RQ-NOTIF-004, RQ-NOTIF-005
A54: BE:E03 | B54: 체계분류 | C54: =SUMPRODUCT(--ISNUMBER(FIND(A54&" ",'요구사항 추적표'!$V$5:$V$57))) | D54: 정상 | H54: RQ-AUTH-004, RQ-DASH-001, RQ-DASH-004, RQ-DASH-006, RQ-EQUIP-001, RQ-EQUIP-002, RQ-SCORE-001, RQ-LL-001, RQ-SPEC-001, RQ-GATE-001, RQ-GATE-002, RQ-GATE-003, RQ-GATE-004, RQ-GATE-006, RQ-GATE-007, RQ-GATE-010, RQ-GATE-011, RQ-GATE-013, RQ-CONFIG-002, RQ-CONFIG-003, RQ-NOTIF-002
A55: BE:E04 | B55: 기자재 | C55: =SUMPRODUCT(--ISNUMBER(FIND(A55&" ",'요구사항 추적표'!$V$5:$V$57))) | D55: 정상 | H55: RQ-AUTH-004, RQ-DASH-001, RQ-DASH-002, RQ-DASH-003, RQ-DASH-004, RQ-DASH-006, RQ-EQUIP-001, RQ-EQUIP-002, RQ-SCORE-001, RQ-LL-001, RQ-LL-005, RQ-SPEC-001, RQ-GATE-001, RQ-GATE-002, RQ-GATE-003, RQ-GATE-004, RQ-GATE-005, RQ-GATE-006, RQ-GATE-007, RQ-GATE-010, RQ-GATE-011, RQ-GATE-013, RQ-CONFIG-002, RQ-CONFIG-003, RQ-NOTIF-002, RQ-NOTIF-004, RQ-NOTIF-005
A56: BE:E05 | B56: 평가기준 버전 | C56: =SUMPRODUCT(--ISNUMBER(FIND(A56&" ",'요구사항 추적표'!$V$5:$V$57))) | D56: 정상 | H56: RQ-AUTH-003, RQ-AUTH-004, RQ-DASH-001, RQ-DASH-004, RQ-DASH-006, RQ-EQUIP-001, RQ-EQUIP-002, RQ-EQUIP-003, RQ-SCORE-001, RQ-SCORE-002, RQ-SCORE-003, RQ-SCORE-004, RQ-LL-001, RQ-SPEC-001, RQ-GATE-001, RQ-GATE-002, RQ-GATE-003, RQ-GATE-004, RQ-GATE-006, RQ-GATE-007, RQ-GATE-010, RQ-GATE-011, RQ-GATE-013, RQ-CONFIG-001, RQ-CONFIG-002, RQ-CONFIG-003, RQ-CONFIG-004, RQ-NOTIF-002
A57: BE:E06 | B57: 위험평가 회차 | C57: =SUMPRODUCT(--ISNUMBER(FIND(A57&" ",'요구사항 추적표'!$V$5:$V$57))) | D57: 정상 | H57: RQ-AUTH-004, RQ-DASH-001, RQ-DASH-002, RQ-DASH-003, RQ-DASH-004, RQ-DASH-005, RQ-DASH-006, RQ-EQUIP-001, RQ-EQUIP-002, RQ-EQUIP-003, RQ-SCORE-001, RQ-SCORE-002, RQ-SCORE-003, RQ-SCORE-004, RQ-LL-001, RQ-LL-005, RQ-SPEC-001, RQ-GATE-001, RQ-GATE-002, RQ-GATE-003, RQ-GATE-004, RQ-GATE-005, RQ-GATE-006, RQ-GATE-007, RQ-GATE-010, RQ-GATE-011, RQ-GATE-013, RQ-CONFIG-001, RQ-CONFIG-002, RQ-CONFIG-003, RQ-NOTIF-002, RQ-NOTIF-004
A58: BE:E07 | B58: 평가요소 | C58: =SUMPRODUCT(--ISNUMBER(FIND(A58&" ",'요구사항 추적표'!$V$5:$V$57))) | D58: 정상 | H58: RQ-EQUIP-002, RQ-EQUIP-003, RQ-SCORE-001, RQ-SCORE-002, RQ-SCORE-003, RQ-SCORE-004, RQ-GATE-001, RQ-GATE-002
A59: BE:E08 | B59: 교훈기준 개정 | C59: =SUMPRODUCT(--ISNUMBER(FIND(A59&" ",'요구사항 추적표'!$V$5:$V$57))) | D59: 정상 | H59: RQ-EQUIP-003, RQ-LL-001, RQ-LL-002, RQ-LL-003, RQ-LL-004, RQ-LL-005, RQ-LL-007, RQ-GATE-008, RQ-CONFIG-004
A60: BE:E09 | B60: 기자재 점검항목 | C60: =SUMPRODUCT(--ISNUMBER(FIND(A60&" ",'요구사항 추적표'!$V$5:$V$57))) | D60: 정상 | H60: RQ-DASH-002, RQ-EQUIP-002, RQ-EQUIP-003, RQ-LL-001, RQ-LL-002, RQ-LL-003, RQ-LL-004, RQ-LL-005, RQ-LL-006, RQ-LL-007, RQ-GATE-001, RQ-GATE-003, RQ-GATE-004, RQ-GATE-008, RQ-GATE-013
...

Sheet 작성가이드
B1: # 항목 설명
B2: No | C2: 항목명 | D2: 항 목 설 명 | E2: 예제 | F2: 필수
B3: 1 | C3: [요구사항] No | D3: 추적표 내 일련번호를 기재한다. | E3: 1 | F3: 필수
B4: 2 | C4: [요구사항] 대 / 중 / 소분류 | D4: 요구사항 정의서의 대·중·소분류를 그대로 옮긴다. | E4: 콜센터 / 상담이력 / 조회 | F4: 필수
B5: 3 | C5: [요구사항] 요구사항ID · 요구사항명 | D5: 요구사항 정의서의 요구사항ID·명을 그대로 옮긴다. **ID는 정의서와 반드시 일치**시킨다. | E5: RQ_CC_001 / 상담이력 조회 | F5: 필수
B6: 4 | C6: [요구사항] 적용여부 | D6: 해당 요구사항의 시스템 반영 여부를 Y / N / N/A 로 기재한다. | E6: Y | F6: 필수
B7: 5 | C7: [요구사항] 프로세스ID · 프로세스명 | D7: 프로세스 정의서의 프로세스ID·명을 기재한다. | E7: PRC-CC-010 / 상담이력 조회 | F7: 해당 시
B8: 6 | C8: [설계] 화면ID · 화면명 | D8: **프로그램 설계서 › 프로그램설계목록**의 연관정보 `화면ID` 와 프로그램명을 옮긴다. 본 프로젝트는 화면 목록·화면 설계서를 디지털 목업으로 대체하므로 프로그램설계목록이 화면ID의 단일 출처다. | E8: MRO-DSH-010-M1 / 상담이력 조회 화면 | F8: 해당 시
B9: 7 | C9: [설계] 배치프로그램ID · 배치프로그램명 | D9: 프로그램 설계서 › 프로그램설계목록의 연관정보 `배치프로그램ID` 를 옮긴다. | E9: MRO-BAT-010-B1 / 상담이력 집계 | F9: 해당 시
B10: 8 | C10: [설계] 인터페이스ID · 인터페이스명 | D10: 인터페이스 설계서의 인터페이스ID·명을 기재한다. | E10: IF-CC-20-05 / 상담이력 수신 | F10: 해당 시
B11: 9 | C11: [설계] 테이블ID | D11: 해당 요구사항이 생성·변경하는 주 테이블ID를 기재한다. **테이블 정의서 › 테이블목록**의 테이블ID와 일치시킨다. 복수는 쉼표로 구분한다. | E11: TB_CC_HIST | F11: 해당 시
B12: 10 | C12: [개발] 단위테스트케이스ID · 케이스명 | D12: **단위테스트 결과 보고서 › 단위테스트결과서**의 `단위테스트 케이스ID`·케이스명을 그대로 옮긴다. | E12: UT-CC-001 / 상담이력 조회 정상 | F12: 해당 시
B13: 11 | C13: [테스트] 통합테스트케이스ID · 케이스명 | D13: **통합테스트 시나리오**의 `통합테스트 케이스ID`·케이스명을 그대로 옮긴다. 통합테스트 결과 보고서도 같은 ID를 쓴다. | E13: TEST0001_TC01 / 상담이력 조회 정상 | F13: 해당 시
B15: # 작성 규칙
B16: ※ 헤더는 2단 구성이다. 1단 = 요구사항 / 설계 / 개발 / 테스트, 2단 = 세부 항목.
B17: ※ 해당 사항이 없는 칸은 공란으로 두지 않고 "N/A" 로 기재한다.
B18: ※ 단계별로 갱신한다 — 분석 시 요구사항·프로세스, 설계 시 화면·배치·인터페이스·테이블, 개발 시 단위테스트, 테스트 시 통합테스트 항목을 채운다.
B19: ※ 제출 시 파일명 단계코드(CM)를 해당 단계(AN / DS / DV / TS)로 변경한다.
B20: ※ 【ID 출처 대응표】 요구사항ID→요구사항 정의서 / 프로세스ID→프로세스 정의서 / 화면ID·배치프로그램ID→프로그램 설계서(프로그램설계목록) / 인터페이스ID→인터페이스 설계서 / 테이블ID→테이블 정의서 / 단위테스트 케이스ID→단위테스트 결과 보고서 / 통합테스트 케이스ID→통합테스트 시나리오·결과 보고서.
B21: ※ 데이터 행은 30행만 사전 생성했다. 부족하면 마지막 행을 복사해 늘린다.
B22: ※ 【프로젝트 적용 1】 프로세스 정의서와 프로그램 설계서가 아직 없으므로, 프로세스ID(PRC-PQG-nnn)와 화면ID(PQG-화면군-nnn-M1/P1)는 목업과 설명 보고서 기준 잠정 ID로 부여했다. M1은 기본 화면·영역, P1은 팝업 창이다. 서버 공통 처리만 있는 요구사항은 화면ID를 N/A로 둔다.
B23: ※ 【프로젝트 적용 2】 "미정"은 해당 항목이 필요할 가능성이 있으나 설계 문서가 없거나 업무 결정(DEC) 전인 경우이며, 이름 칸에 후보명과 결정번호를 적었다. "미작성"은 해당 단계(개발·테스트)가 도래하지 않은 경우이다. "N/A"는 해당 없음이다.
B24: ※ 【프로젝트 적용 3】 추가 열 U~Z: U=화면 논리 개체(프런트엔드 데이터 모델 정의서 v0.3의 FE-Exx), V=서버 논리 개체(백엔드 데이터 모델 정의서 v0.1의 BE:Exx와, FE 개체의 대응 백엔드 개체·"BE 신설 요청"), W=통합 결정번호(DEC), X=확정 여부, Y=구현 영역(화면, 서버, 화면+서버), Z=기존 요구사항ID(FE-, BE-). 테이블ID(P열)는 테이블 정의서 작성 후 V열 개체에 대응하는 테이블로 채운다.
B25: ※ 【프로젝트 적용 4】 요구사항ID는 통합 요구사항 정의서 v0.6(soft2preqcgate1_요구사항정의서_20261001_1133.xlsx)의 RQ- ID와 일치시킨다. 프런트엔드 48건과 백엔드 31건이 53건으로 통합되었으며, 원천 ID는 Z열에서 추적한다.
